Workbook

Sheet Hoja1
A1: =IF(OR(AI2<>""),1," ") -> 1 | B1: Paciente | C1: FechaValidacion | D1: Afiliado | E1: DNI | F1: FechaDeNacimiento | G1: Hora | H1: CampoVisual | I1: Topografia | J1: OCT | K1: IOL | L1: HRT | M1: Paquimetria | N1: Lotmar | O1: Retinografia | P1: Aberrometria | Q1: Angiografia | R1: Microscopia | S1: genero | T1: paquiOD | U1: paquiOI | V1: lotmarOD | W1: lotmarOI | X1: iolOD | Y1: iolOI | Z1: microOD | AA1: microOI | AB1: AVSCD | AC1: AVSCI | AD1: AVMCD | AE1: AVMCI | AF1: presionD | AG1: presionI | AH1: consulta | AI1: Observaciones | AJ1: negroOD | AK1: negroOI | AL1: negroOA | AM1: mascuOI | AN1: mascuOD | AO1: mascuOA | AP1: despOI | AQ1: despOD | AR1: despOA | AS1: OS | AT1: P | AU1: B | AV1: CAM | AW1: SP | AX1: ioma | AY1: OD | AZ1: OI | BA1: tittle
A2: =IF(OR(AI2<>""),1," ") -> 1 | B2: =Hoja4!H3 -> CORDOBA NORMA MIRTA | C2: =Hoja4!I3 -> 04/05/2026 | D2: =Hoja4!J3 -> 15037290270300 | E2: =Hoja4!K3 -> 5603434 | F2: =Hoja4!L3 -> 31/03/1947 | G2: =Hoja4!M3 -> 09:00 | J2: x | K2: x | L2: x | R2: x | S2: m | AH2: 4 | AI2: OCT desprendimiento OI | AP2: x | BA2: PAMI - N1 - 4 AL 6 MAY 2026 | BC2: 9:00
A3: =IF(OR(AI3<>""),1," ") | B3: =Hoja4!H4 -> GOMEZ MIRTA DEL VALLE | C3: =Hoja4!I4 -> 04/05/2026 | D3: =Hoja4!J4 -> 15072801600999 | E3: =Hoja4!K4 -> 20159718 | F3: =Hoja4!L4 -> 18/01/1968 | G3: =Hoja4!M4 -> 09:20 | I3: x | J3: x | O3: x | S3: m | AH3: 4 | BA3: PAMI - N1 - 4 AL 6 MAY 2026 | BC3: 9:20
A4: =IF(OR(AI4<>""),1," ") | B4: =Hoja4!H5 -> MORALES FELIPE JOSE | C4: =Hoja4!I5 -> 04/05/2026 | D4: =Hoja4!J5 -> 14013195510100 | E4: =Hoja4!K5 -> 14934826 | F4: =Hoja4!L5 -> 06/12/1961 | G4: =Hoja4!M5 -> 09:40 | J4: x | K4: x | L4: x | R4: x | S4: h | AH4: 4 | BA4: PAMI - N1 - 4 AL 6 MAY 2026 | BC4: 9:40
A5: =IF(OR(AI5<>""),1," ") | B5: =Hoja4!H6 -> GONZALEZ MARTA ELENA | C5: =Hoja4!I6 -> 04/05/2026 | D5: =Hoja4!J6 -> 15016001460000 | E5: =Hoja4!K6 -> 4795381 | F5: =Hoja4!L6 -> 31/01/1944 | G5: =Hoja4!M6 -> 10:00 | J5: x | K5: x | L5: x | R5: x | S5: m | AH5: 4 | BA5: PAMI - N1 - 4 AL 6 MAY 2026 | BC5: 10:00
A6: =IF(OR(AI6<>""),1," ") | B6: =Hoja4!H7 -> ALTAMIRANO MIRTA IZOLINA | C6: =Hoja4!I7 -> 05/05/2026 | D6: =Hoja4!J7 -> 15044671360300 | E6: =Hoja4!K7 -> 6173026 | F6: =Hoja4!L7 -> 26/07/1949 | G6: =Hoja4!M7 -> 09:00 | I6: x | J6: x | O6: x | S6: m | AH6: 4 | BA6: PAMI - N1 - 4 AL 6 MAY 2026 | BC6: 10:20
A7: =IF(OR(AI7<>""),1," ") | B7: =Hoja4!H8 -> SOTO ELBA MARIA | C7: =Hoja4!I8 -> 05/05/2026 | D7: =Hoja4!J8 -> 14024390230100 | E7: =Hoja4!K8 -> 16591888 | F7: =Hoja4!L8 -> 12/08/1964 | G7: =Hoja4!M8 -> 09:20 | I7: x | J7: x | O7: x | S7: m | AH7: 4 | BA7: PAMI - N1 - 4 AL 6 MAY 2026 | BC7: 10:40
A8: =IF(OR(AI8<>""),1," ") | B8: =Hoja4!H9 -> LOOSE ALBINA RAQUEL | C8: =Hoja4!I9 -> 05/05/2026 | D8: =Hoja4!J9 -> 15072698730600 | E8: =Hoja4!K9 -> 10741460 | F8: =Hoja4!L9 -> 10/12/1952 | G8: =Hoja4!M9 -> 09:40 | I8: x | J8: x | O8: x | S8: m | AH8: 4 | BA8: PAMI - N1 - 4 AL 6 MAY 2026 | BC8: 11:00
A9: =IF(OR(AI9<>""),1," ") | B9: =Hoja4!H10 -> BIELECKI PABLO TOMAS | C9: =Hoja4!I10 -> 05/05/2026 | D9: =Hoja4!J10 -> 15058415880200 | E9: =Hoja4!K10 -> 8549382 | F9: =Hoja4!L10 -> 28/04/1948 | G9: =Hoja4!M10 -> 10:00 | I9: x | J9: x | O9: x | S9: h | AH9: 4 | BA9: PAMI - N1 - 4 AL 6 MAY 2026 | BC9: 11:20
A10: =IF(OR(AI10<>""),1," ") | B10: =Hoja4!H11 -> BATISTA PEREZ HUGO ANTONIO | C10: =Hoja4!I11 -> 05/05/2026 | D10: =Hoja4!J11 -> 46590013490200 | E10: =Hoja4!K11 -> 92576544 | F10: =Hoja4!L11 -> 14/12/1948 | G10: =Hoja4!M11 -> 10:20 | J10: x | K10: x | L10: x | R10: x | S10: h | AH10: 4 | BA10: PAMI - N1 - 4 AL 6 MAY 2026 | BC10: 11:40
A11: =IF(OR(AI11<>""),1," ") | B11: =Hoja4!H12 -> RAMIREZ ANDRES DAMIAN | C11: =Hoja4!I12 -> 05/05/2026 | D11: =Hoja4!J12 -> 14025244420500 | E11: =Hoja4!K12 -> 16706793 | F11: =Hoja4!L12 -> 04/01/1964 | G11: =Hoja4!M12 -> 10:40 | J11: x | K11: x | L11: x | R11: x | S11: h | AH11: 4 | BA11: PAMI - N1 - 4 AL 6 MAY 2026 | BC11: 12:00
A12: =IF(OR(AI12<>""),1," ") | B12: =Hoja4!H13 -> SALDIVIA MARTA SUSANA | C12: =Hoja4!I13 -> 05/05/2026 | D12: =Hoja4!J13 -> 14013716580100 | E12: =Hoja4!K13 -> 14849047 | F12: =Hoja4!L13 -> 07/05/1962 | G12: =Hoja4!M13 -> 11:00 | I12: x | J12: x | O12: x | S12: m | AH12: 4 | BA12: PAMI - N1 - 4 AL 6 MAY 2026 | BC12: 12:20
A13: =IF(OR(AI13<>""),1," ") | B13: =Hoja4!H14 -> ROMERO SANTA ISABEL | C13: =Hoja4!I14 -> 05/05/2026 | D13: =Hoja4!J14 -> 14016620780200 | E13: =Hoja4!K14 -> 16602944 | F13: =Hoja4!L14 -> 01/08/1963 | G13: =Hoja4!M14 -> 11:20 | I13: x | J13: x | O13: x | S13: m | AH13: 4 | BA13: PAMI - N1 - 4 AL 6 MAY 2026 | BC13: 12:40
A14: =IF(OR(AI14<>""),1," ") | B14: =Hoja4!H15 -> PARISSI HAYDEE ROSA | C14: =Hoja4!I15 -> 05/05/2026 | D14: =Hoja4!J15 -> 15012665480200 | E14: =Hoja4!K15 -> 4542759 | F14: =Hoja4!L15 -> 14/07/1943 | G14: =Hoja4!M15 -> 11:40 | I14: x | J14: x | O14: x | S14: m | AH14: 4 | BA14: PAMI - N1 - 4 AL 6 MAY 2026 | BC14: 13:00
A15: =IF(OR(AI15<>""),1," ") | B15: =Hoja4!H16 -> DEGLISE LILIANA INES | C15: =Hoja4!I16 -> 05/05/2026 | D15: =Hoja4!J16 -> 14010879270800 | E15: =Hoja4!K16 -> 20159718 | F15: =Hoja4!L16 -> 17/01/1961 | G15: =Hoja4!M16 -> 12:00 | I15: x | J15: x | O15: x | S15: m | AH15: 4 | BA15: PAMI - N1 - 4 AL 6 MAY 2026 | BC15: 13:20
A16: =IF(OR(AI16<>""),1," ") | B16: =Hoja4!H17 -> PIÑERO ROLANDO ALBERTO | C16: =Hoja4!I17 -> 05/05/2026 | D16: =Hoja4!J17 -> 14091740080700 | E16: =Hoja4!K17 -> 12495723 | F16: =Hoja4!L17 -> 18/11/1956 | G16: =Hoja4!M17 -> 12:20 | I16: x | J16: x | O16: x | S16: h | AH16: 4 | BA16: PAMI - N1 - 4 AL 6 MAY 2026 | BC16: 13:40
A17: =IF(OR(AI17<>""),1," ") | B17: =Hoja4!H18 -> ROLDAN JORGELINA RAMONA | C17: =Hoja4!I18 -> 05/05/2026 | D17: =Hoja4!J18 -> 15029734750500 | E17: =Hoja4!K18 -> 2354733 | F17: =Hoja4!L18 -> 04/03/1933 | G17: =Hoja4!M18 -> 12:40 | I17: x | J17: x | O17: x | S17: m | AH17: 4 | BA17: PAMI - N1 - 4 AL 6 MAY 2026 | BC17: 14:00
A18: =IF(OR(AI18<>""),1," ") | B18: =Hoja4!H19 -> MAURICI ANA MARIA | C18: =Hoja4!I19 -> 05/05/2026 | D18: =Hoja4!J19 -> 15050948840100 | E18: =Hoja4!K19 -> 6399953 | F18: =Hoja4!L19 -> 04/10/1950 | G18: =Hoja4!M19 -> 13:00 | I18: x | J18: x | O18: x | S18: m | AH18: 4 | BA18: PAMI - N1 - 4 AL 6 MAY 2026 | BC18: 14:20
A19: =IF(OR(AI19<>""),1," ") | B19: =Hoja4!H20 -> CAPDEVILA RICARDO | C19: =Hoja4!I20 -> 05/05/2026 | D19: =Hoja4!J20 -> 15060748250100 | E19: =Hoja4!K20 -> 10673792 | F19: =Hoja4!L20 -> 08/06/1953 | G19: =Hoja4!M20 -> 13:20 | I19: x | J19: x | O19: x | S19: h | AH19: 4 | BA19: PAMI - N1 - 4 AL 6 MAY 2026 | BC19: 14:40
A20: =IF(OR(AI20<>""),1," ") | B20: =Hoja4!H21 -> IBAÑEZ ROSARIO DEL CARMEN | C20: =Hoja4!I21 -> 05/05/2026 | D20: =Hoja4!J21 -> 15072166470000 | E20: =Hoja4!K21 -> 11741176 | F20: =Hoja4!L21 -> 04/04/1955 | G20: =Hoja4!M21 -> 13:40 | J20: x | K20: x | L20: x | R20: x | S20: m | AH20: 4 | BA20: PAMI - N1 - 4 AL 6 MAY 2026 | BC20: 15:00
A21: =IF(OR(AI21<>""),1," ") | B21: =Hoja4!H22 -> GUTIERREZ HUGO DONATO | C21: =Hoja4!I22 -> 05/05/2026 | D21: =Hoja4!J22 -> 14028255410700 | E21: =Hoja4!K22 -> 13836277 | F21: =Hoja4!L22 -> 14/12/1959 | G21: =Hoja4!M22 -> 14:00 | I21: x | J21: x | O21: x | S21: h | AH21: 4 | BA21: PAMI - N1 - 4 AL 6 MAY 2026 | BC21: 15:20
A22: =IF(OR(AI22<>""),1," ") | B22: =Hoja4!H23 -> PORTILLO NORA MARTA | C22: =Hoja4!I23 -> 05/05/2026 | D22: =Hoja4!J23 -> 15538779670300 | E22: =Hoja4!K23 -> 5949232 | F22: =Hoja4!L23 -> 15/11/1948 | G22: =Hoja4!M23 -> 14:20 | I22: x | J22: x | O22: x | S22: m | AH22: 4 | BA22: PAMI - N1 - 4 AL 6 MAY 2026 | BC22: 15:40
A23: =IF(OR(AI23<>""),1," ") | B23: =Hoja4!H24 -> GARCIA CALDAS ROSALBINA | C23: =Hoja4!I24 -> 05/05/2026 | D23: =Hoja4!J24 -> 15074574940399 | E23: =Hoja4!K24 -> 93679003 | F23: =Hoja4!L24 -> 25/03/1963 | G23: =Hoja4!M24 -> 14:40 | I23: x | J23: x | O23: x | S23: m | AH23: 4 | BA23: PAMI - N1 - 4 AL 6 MAY 2026 | BC23: 16:00
A24: =IF(OR(AI24<>""),1," ") | B24: =Hoja4!H25 -> TOTORIKAGUENA MARIA DEL CARMEN | C24: =Hoja4!I25 -> 06/05/2026 | D24: =Hoja4!J25 -> 15067228920100 | E24: =Hoja4!K25 -> 6685943 | F24: =Hoja4!L25 -> 10/10/1951 | G24: =Hoja4!M25 -> 09:00 | I24: x | J24: x | O24: x | S24: m | AH24: 4 | BA24: PAMI - N1 - 4 AL 6 MAY 2026 | BC24: 16:20
A25: =IF(OR(AI25<>""),1," ") | B25: =Hoja4!H26 -> MUÑOZ RICARDO RAFAEL | C25: =Hoja4!I26 -> 06/05/2026 | D25: =Hoja4!J26 -> 14009626270900 | E25: =Hoja4!K26 -> 14165362 | F25: =Hoja4!L26 -> 22/03/1961 | G25: =Hoja4!M26 -> 09:20 | J25: x | K25: x | L25: x | R25: x | S25: h | AH25: 4 | BA25: PAMI - N1 - 4 AL 6 MAY 2026
A26: =IF(OR(AI26<>""),1," ") | B26: =Hoja4!H27 -> DA COSTA SUSANA BEATRIZ | C26: =Hoja4!I27 -> 06/05/2026 | D26: =Hoja4!J27 -> 14025508920300 | E26: =Hoja4!K27 -> 16797601 | F26: =Hoja4!L27 -> 17/10/1964 | G26: =Hoja4!M27 -> 09:40 | I26: x | J26: x | O26: x | S26: m | AH26: 4 | BA26: PAMI - N1 - 4 AL 6 MAY 2026
A27: =IF(OR(AI27<>""),1," ") | B27: =Hoja4!H28 -> LUNA FELICIANA | C27: =Hoja4!I28 -> 06/05/2026 | D27: =Hoja4!J28 -> 15050647900100 | E27: =Hoja4!K28 -> 6220920 | F27: =Hoja4!L28 -> 23/08/1948 | G27: =Hoja4!M28 -> 10:00 | I27: x | J27: x | O27: x | S27: m | AH27: 4 | BA27: PAMI - N1 - 4 AL 6 MAY 2026
A28: =IF(OR(AI28<>""),1," ") | B28: =Hoja4!H29 -> LUNA FELICIANA | C28: =Hoja4!I29 -> 05/05/2026 | D28: =Hoja4!J29 -> 15050647900100 | E28: =Hoja4!K29 -> 0 | F28: =Hoja4!L29 -> 00/01/1900 | G28: =Hoja4!M29 -> 00:00 | AH28: 1 | BA28: PAMI - N1 - 4 AL 6 MAY 2026
A29: =IF(OR(AI29<>""),1," ") | B29: =Hoja4!H30 -> MUÑOZ RICARDO RAFAEL | C29: =Hoja4!I30 -> 05/05/2026 | D29: =Hoja4!J30 -> 14009626270900 | E29: =Hoja4!K30 -> 0 | F29: =Hoja4!L30 -> 00/01/1900 | G29: =Hoja4!M30 -> 00:00 | AH29: 1 | BA29: PAMI - N1 - 4 AL 6 MAY 2026
A30: =IF(OR(AI30<>""),1," ") | B30: =Hoja4!H31 -> DA COSTA SUSANA BEATRIZ | C30: =Hoja4!I31 -> 05/05/2026 | D30: =Hoja4!J31 -> 14025508920300 | E30: =Hoja4!K31 -> 0 | F30: =Hoja4!L31 -> 00/01/1900 | G30: =Hoja4!M31 -> 00:00 | AH30: 1 | BA30: PAMI - N1 - 4 AL 6 MAY 2026
A31: =IF(OR(AI31<>""),1," ") | B31: =Hoja4!H32 -> TOTORIKAGUENA MARIA DEL CARMEN | C31: =Hoja4!I32 -> 05/05/2026 | D31: =Hoja4!J32 -> 15067228920100 | E31: =Hoja4!K32 -> 0 | F31: =Hoja4!L32 -> 00/01/1900 | G31: =Hoja4!M32 -> 00:00 | AH31: 1 | BA31: PAMI - N1 - 4 AL 6 MAY 2026
A32: =IF(OR(AI32<>""),1," ") | B32: =Hoja4!H33 -> 0 | C32: =Hoja4!I33 -> 00/01/1900 | D32: =Hoja4!J33 -> 0 | E32: =Hoja4!K33 -> 0 | F32: =Hoja4!L33 -> 00/01/1900 | G32: =Hoja4!M33 -> 00:00
A33: =IF(OR(AI33<>""),1," ") | B33: =Hoja4!H34 -> 0 | C33: =Hoja4!I34 -> 00/01/1900 | D33: =Hoja4!J34 -> 0 | E33: =Hoja4!K34 -> 0 | F33: =Hoja4!L34 -> 00/01/1900 | G33: =Hoja4!M34 -> 00:00
A34: =IF(OR(AI34<>""),1," ") | B34: =Hoja4!H35 -> 0 | C34: =Hoja4!I35 -> 00/01/1900 | D34: =Hoja4!J35 -> 0 | E34: =Hoja4!K35 -> 0 | F34: =Hoja4!L35 -> 00/01/1900 | G34: =Hoja4!M35 -> 00:00
A35: =IF(OR(AI35<>""),1," ") | B35: =Hoja4!H36 -> 0 | C35: =Hoja4!I36 -> 00/01/1900 | D35: =Hoja4!J36 -> 0 | E35: =Hoja4!K36 -> 0 | F35: =Hoja4!L36 -> 00/01/1900 | G35: =Hoja4!M36 -> 00:00
A36: =IF(OR(AI36<>""),1," ") | B36: =Hoja4!H37 -> 0 | C36: =Hoja4!I37 -> 00/01/1900 | D36: =Hoja4!J37 -> 0 | E36: =Hoja4!K37 -> 0 | F36: =Hoja4!L37 -> 00/01/1900 | G36: =Hoja4!M37 -> 00:00
A37: =IF(OR(AI37<>""),1," ") | B37: =Hoja4!H38 -> 0 | C37: =Hoja4!I38 -> 00/01/1900 | D37: =Hoja4!J38 -> 0 | E37: =Hoja4!K38 -> 0 | F37: =Hoja4!L38 -> 00/01/1900 | G37: =Hoja4!M38 -> 00:00
A38: =IF(OR(AI38<>""),1," ") | B38: =Hoja4!H39 -> 0 | C38: =Hoja4!I39 -> 00/01/1900 | D38: =Hoja4!J39 -> 0 | E38: =Hoja4!K39 -> 0 | F38: =Hoja4!L39 -> 00/01/1900 | G38: =Hoja4!M39 -> 00:00
A39: =IF(OR(AI39<>""),1," ") | B39: =Hoja4!H40 -> 0 | C39: =Hoja4!I40 -> 00/01/1900 | D39: =Hoja4!J40 -> 0 | E39: =Hoja4!K40 -> 0 | F39: =Hoja4!L40 -> 00/01/1900 | G39: =Hoja4!M40 -> 00:00
A40: =IF(OR(AI40<>""),1," ") | B40: =Hoja4!H41 -> 0 | C40: =Hoja4!I41 -> 00/01/1900 | D40: =Hoja4!J41 -> 0 | E40: =Hoja4!K41 -> 0 | F40: =Hoja4!L41 -> 00/01/1900 | G40: =Hoja4!M41 -> 00:00
...

Sheet Hoja4
A1: DATOS EN CUALQUIER FORMATO | H1: DATOS EN FORMATO TEXTO (pegar solo valores en el excel original) | O1: 9:00
A2: Paciente | B2: FechaValidacion | C2: Afiliado | D2: DNI | E2: FechaDeNacimiento | F2: Hora | H2: Paciente | I2: FechaValidacion | J2: Afiliado | K2: DNI | L2: FechaDeNacimiento | M2: Hora | O2: 9:20
A3: CORDOBA NORMA MIRTA | B3: 04/05/2026 | C3: 15037290270300 | D3: 5603434 | E3: 17257 | F3: 9:00 | H3: =TEXT(A3,"0") -> CORDOBA NORMA MIRTA | I3: =TEXT(B3,"DD/MM/YYYY") -> 04/05/2026 | J3: =TEXT(C3,"0") -> 15037290270300 | K3: =TEXT(D3,"0") -> 5603434 | L3: =TEXT(E3,"DD/MM/YYYY") -> 31/03/1947 | M3: =TEXT(F3,"hh:mm") -> 09:00 | O3: 9:40
A4: GOMEZ MIRTA DEL VALLE | B4: 04/05/2026 | C4: 15072801600999 | D4: 20159718 | E4: 24855 | F4: 9:20 | H4: =TEXT(A4,"0") -> GOMEZ MIRTA DEL VALLE | I4: =TEXT(B4,"DD/MM/YYYY") -> 04/05/2026 | J4: =TEXT(C4,"0") -> 15072801600999 | K4: =TEXT(D4,"0") -> 20159718 | L4: =TEXT(E4,"DD/MM/YYYY") -> 18/01/1968 | M4: =TEXT(F4,"hh:mm") -> 09:20 | O4: 10:00
A5: MORALES FELIPE JOSE | B5: 04/05/2026 | C5: 14013195510100 | D5: 14934826 | E5: 22621 | F5: 9:40 | H5: =TEXT(A5,"0") -> MORALES FELIPE JOSE | I5: =TEXT(B5,"DD/MM/YYYY") -> 04/05/2026 | J5: =TEXT(C5,"0") -> 14013195510100 | K5: =TEXT(D5,"0") -> 14934826 | L5: =TEXT(E5,"DD/MM/YYYY") -> 06/12/1961 | M5: =TEXT(F5,"hh:mm") -> 09:40 | O5: 10:20
A6: GONZALEZ MARTA ELENA | B6: 04/05/2026 | C6: 15016001460000 | D6: 4795381 | E6: 16102 | F6: 10:00 | H6: =TEXT(A6,"0") -> GONZALEZ MARTA ELENA | I6: =TEXT(B6,"DD/MM/YYYY") -> 04/05/2026 | J6: =TEXT(C6,"0") -> 15016001460000 | K6: =TEXT(D6,"0") -> 4795381 | L6: =TEXT(E6,"DD/MM/YYYY") -> 31/01/1944 | M6: =TEXT(F6,"hh:mm") -> 10:00 | O6: 10:40
A7: ALTAMIRANO MIRTA IZOLINA | B7: 05/05/2026 | C7: 15044671360300 | D7: 6173026 | E7: 18105 | F7: 9:00 | H7: =TEXT(A7,"0") -> ALTAMIRANO MIRTA IZOLINA | I7: =TEXT(B7,"DD/MM/YYYY") -> 05/05/2026 | J7: =TEXT(C7,"0") -> 15044671360300 | K7: =TEXT(D7,"0") -> 6173026 | L7: =TEXT(E7,"DD/MM/YYYY") -> 26/07/1949 | M7: =TEXT(F7,"hh:mm") -> 09:00 | O7: 11:00
A8: SOTO ELBA MARIA | B8: 05/05/2026 | C8: 14024390230100 | D8: 16591888 | E8: 23601 | F8: 9:20 | H8: =TEXT(A8,"0") -> SOTO ELBA MARIA | I8: =TEXT(B8,"DD/MM/YYYY") -> 05/05/2026 | J8: =TEXT(C8,"0") -> 14024390230100 | K8: =TEXT(D8,"0") -> 16591888 | L8: =TEXT(E8,"DD/MM/YYYY") -> 12/08/1964 | M8: =TEXT(F8,"hh:mm") -> 09:20 | O8: 11:20
A9: LOOSE ALBINA RAQUEL | B9: 05/05/2026 | C9: 15072698730600 | D9: 10741460 | E9: 19338 | F9: 9:40 | H9: =TEXT(A9,"0") -> LOOSE ALBINA RAQUEL | I9: =TEXT(B9,"DD/MM/YYYY") -> 05/05/2026 | J9: =TEXT(C9,"0") -> 15072698730600 | K9: =TEXT(D9,"0") -> 10741460 | L9: =TEXT(E9,"DD/MM/YYYY") -> 10/12/1952 | M9: =TEXT(F9,"hh:mm") -> 09:40 | O9: 11:40
A10: BIELECKI PABLO TOMAS | B10: 05/05/2026 | C10: 15058415880200 | D10: 8549382 | E10: 17651 | F10: 10:00 | H10: =TEXT(A10,"0") -> BIELECKI PABLO TOMAS | I10: =TEXT(B10,"DD/MM/YYYY") -> 05/05/2026 | J10: =TEXT(C10,"0") -> 15058415880200 | K10: =TEXT(D10,"0") -> 8549382 | L10: =TEXT(E10,"DD/MM/YYYY") -> 28/04/1948 | M10: =TEXT(F10,"hh:mm") -> 10:00 | O10: 12:00
A11: BATISTA PEREZ HUGO ANTONIO | B11: 05/05/2026 | C11: 46590013490200 | D11: 92576544 | E11: 17881 | F11: 10:20 | H11: =TEXT(A11,"0") -> BATISTA PEREZ HUGO ANTONIO | I11: =TEXT(B11,"DD/MM/YYYY") -> 05/05/2026 | J11: =TEXT(C11,"0") -> 46590013490200 | K11: =TEXT(D11,"0") -> 92576544 | L11: =TEXT(E11,"DD/MM/YYYY") -> 14/12/1948 | M11: =TEXT(F11,"hh:mm") -> 10:20 | O11: 12:20
A12: RAMIREZ ANDRES DAMIAN | B12: 05/05/2026 | C12: 14025244420500 | D12: 16706793 | E12: 23380 | F12: 10:40 | H12: =TEXT(A12,"0") -> RAMIREZ ANDRES DAMIAN | I12: =TEXT(B12,"DD/MM/YYYY") -> 05/05/2026 | J12: =TEXT(C12,"0") -> 14025244420500 | K12: =TEXT(D12,"0") -> 16706793 | L12: =TEXT(E12,"DD/MM/YYYY") -> 04/01/1964 | M12: =TEXT(F12,"hh:mm") -> 10:40 | O12: 12:40
A13: SALDIVIA MARTA SUSANA | B13: 05/05/2026 | C13: 14013716580100 | D13: 14849047 | E13: 22773 | F13: 11:00 | H13: =TEXT(A13,"0") -> SALDIVIA MARTA SUSANA | I13: =TEXT(B13,"DD/MM/YYYY") -> 05/05/2026 | J13: =TEXT(C13,"0") -> 14013716580100 | K13: =TEXT(D13,"0") -> 14849047 | L13: =TEXT(E13,"DD/MM/YYYY") -> 07/05/1962 | M13: =TEXT(F13,"hh:mm") -> 11:00 | O13: 13:00
A14: ROMERO SANTA ISABEL | B14: 05/05/2026 | C14: 14016620780200 | D14: 16602944 | E14: 23224 | F14: 11:20 | H14: =TEXT(A14,"0") -> ROMERO SANTA ISABEL | I14: =TEXT(B14,"DD/MM/YYYY") -> 05/05/2026 | J14: =TEXT(C14,"0") -> 14016620780200 | K14: =TEXT(D14,"0") -> 16602944 | L14: =TEXT(E14,"DD/MM/YYYY") -> 01/08/1963 | M14: =TEXT(F14,"hh:mm") -> 11:20 | O14: 13:20
... A28: LUNA FELICIANA | B28: 06/05/2026 | C28: 15050647900100 | D28: 6220920 | E28: 17768 | F28: 10:00 | H28: =TEXT(A28,"0") -> LUNA FELICIANA | I28: =TEXT(B28,"DD/MM/YYYY") -> 06/05/2026 | J28: =TEXT(C28,"0") -> 15050647900100 | K28: =TEXT(D28,"0") -> 6220920 | L28: =TEXT(E28,"DD/MM/YYYY") -> 23/08/1948 | M28: =TEXT(F28,"hh:mm") -> 10:00 | O28: 18:00
A29: LUNA FELICIANA | B29: 05/05/2026 | C29: 15050647900100 | H29: =TEXT(A29,"0") -> LUNA FELICIANA | I29: =TEXT(B29,"DD/MM/YYYY") -> 05/05/2026 | J29: =TEXT(C29,"0") -> 15050647900100 | K29: =TEXT(D29,"0") -> 0 | L29: =TEXT(E29,"DD/MM/YYYY") -> 00/01/1900 | M29: =TEXT(F29,"hh:mm") -> 00:00 | O29: 18:20
A30: MUÑOZ RICARDO RAFAEL | B30: 05/05/2026 | C30: 14009626270900 | H30: =TEXT(A30,"0") -> MUÑOZ RICARDO RAFAEL | I30: =TEXT(B30,"DD/MM/YYYY") -> 05/05/2026 | J30: =TEXT(C30,"0") -> 14009626270900 | K30: =TEXT(D30,"0") -> 0 | L30: =TEXT(E30,"DD/MM/YYYY") -> 00/01/1900 | M30: =TEXT(F30,"hh:mm") -> 00:00 | O30: 18:40
A31: DA COSTA SUSANA BEATRIZ | B31: 05/05/2026 | C31: 14025508920300 | H31: =TEXT(A31,"0") -> DA COSTA SUSANA BEATRIZ | I31: =TEXT(B31,"DD/MM/YYYY") -> 05/05/2026 | J31: =TEXT(C31,"0") -> 14025508920300 | K31: =TEXT(D31,"0") -> 0 | L31: =TEXT(E31,"DD/MM/YYYY") -> 00/01/1900 | M31: =TEXT(F31,"hh:mm") -> 00:00
A32: TOTORIKAGUENA MARIA DEL CARMEN | B32: 05/05/2026 | C32: 15067228920100 | H32: =TEXT(A32,"0") -> TOTORIKAGUENA MARIA DEL CARMEN | I32: =TEXT(B32,"DD/MM/YYYY") -> 05/05/2026 | J32: =TEXT(C32,"0") -> 15067228920100 | K32: =TEXT(D32,"0") -> 0 | L32: =TEXT(E32,"DD/MM/YYYY") -> 00/01/1900 | M32: =TEXT(F32,"hh:mm") -> 00:00
H33: =TEXT(A33,"0") -> 0 | I33: =TEXT(B33,"DD/MM/YYYY") -> 00/01/1900 | J33: =TEXT(C33,"0") -> 0 | K33: =TEXT(D33,"0") -> 0 | L33: =TEXT(E33,"DD/MM/YYYY") -> 00/01/1900 | M33: =TEXT(F33,"hh:mm") -> 00:00
H34: =TEXT(A34,"0") -> 0 | I34: =TEXT(B34,"DD/MM/YYYY") -> 00/01/1900 | J34: =TEXT(C34,"0") -> 0 | K34: =TEXT(D34,"0") -> 0 | L34: =TEXT(E34,"DD/MM/YYYY") -> 00/01/1900 | M34: =TEXT(F34,"hh:mm") -> 00:00
H35: =TEXT(A35,"0") -> 0 | I35: =TEXT(B35,"DD/MM/YYYY") -> 00/01/1900 | J35: =TEXT(C35,"0") -> 0 | K35: =TEXT(D35,"0") -> 0 | L35: =TEXT(E35,"DD/MM/YYYY") -> 00/01/1900 | M35: =TEXT(F35,"hh:mm") -> 00:00
H36: =TEXT(A36,"0") -> 0 | I36: =TEXT(B36,"DD/MM/YYYY") -> 00/01/1900 | J36: =TEXT(C36,"0") -> 0 | K36: =TEXT(D36,"0") -> 0 | L36: =TEXT(E36,"DD/MM/YYYY") -> 00/01/1900 | M36: =TEXT(F36,"hh:mm") -> 00:00
H37: =TEXT(A37,"0") -> 0 | I37: =TEXT(B37,"DD/MM/YYYY") -> 00/01/1900 | J37: =TEXT(C37,"0") -> 0 | K37: =TEXT(D37,"0") -> 0 | L37: =TEXT(E37,"DD/MM/YYYY") -> 00/01/1900 | M37: =TEXT(F37,"hh:mm") -> 00:00
H38: =TEXT(A38,"0") -> 0 | I38: =TEXT(B38,"DD/MM/YYYY") -> 00/01/1900 | J38: =TEXT(C38,"0") -> 0 | K38: =TEXT(D38,"0") -> 0 | L38: =TEXT(E38,"DD/MM/YYYY") -> 00/01/1900 | M38: =TEXT(F38,"hh:mm") -> 00:00
H39: =TEXT(A39,"0") -> 0 | I39: =TEXT(B39,"DD/MM/YYYY") -> 00/01/1900 | J39: =TEXT(C39,"0") -> 0 | K39: =TEXT(D39,"0") -> 0 | L39: =TEXT(E39,"DD/MM/YYYY") -> 00/01/1900 | M39: =TEXT(F39,"hh:mm") -> 00:00
H40: =TEXT(A40,"0") -> 0 | I40: =TEXT(B40,"DD/MM/YYYY") -> 00/01/1900 | J40: =TEXT(C40,"0") -> 0 | K40: =TEXT(D40,"0") -> 0 | L40: =TEXT(E40,"DD/MM/YYYY") -> 00/01/1900 | M40: =TEXT(F40,"hh:mm") -> 00:00
H41: =TEXT(A41,"0") -> 0 | I41: =TEXT(B41,"DD/MM/YYYY") -> 00/01/1900 | J41: =TEXT(C41,"0") -> 0 | K41: =TEXT(D41,"0") -> 0 | L41: =TEXT(E41,"DD/MM/YYYY") -> 00/01/1900 | M41: =TEXT(F41,"hh:mm") -> 00:00
H42: =TEXT(A42,"0") -> 0 | I42: =TEXT(B42,"DD/MM/YYYY") -> 00/01/1900 | J42: =TEXT(C42,"0") -> 0 | K42: =TEXT(D42,"0") -> 0 | L42: =TEXT(E42,"DD/MM/YYYY") -> 00/01/1900 | M42: =TEXT(F42,"hh:mm") -> 00:00
H43: =TEXT(A43,"0") -> 0 | I43: =TEXT(B43,"DD/MM/YYYY") -> 00/01/1900 | J43: =TEXT(C43,"0") -> 0 | K43: =TEXT(D43,"0") -> 0 | L43: =TEXT(E43,"DD/MM/YYYY") -> 00/01/1900 | M43: =TEXT(F43,"hh:mm") -> 00:00
H44: =TEXT(A44,"0") -> 0 | I44: =TEXT(B44,"DD/MM/YYYY") -> 00/01/1900 | J44: =TEXT(C44,"0") -> 0 | K44: =TEXT(D44,"0") -> 0 | L44: =TEXT(E44,"DD/MM/YYYY") -> 00/01/1900 | M44: =TEXT(F44,"hh:mm") -> 00:00
... H850: =TEXT(A850,"0") -> 0 | I850: =TEXT(B850,"DD/MM/YYYY") -> 00/01/1900 | J850: =TEXT(C850,"0") -> 0 | K850: =TEXT(D850,"0") -> 0 | L850: =TEXT(E850,"DD/MM/YYYY") -> 00/01/1900 | M850: =TEXT(F850,"hh:mm") -> 00:00

Sheet Hoja2
G1: ROLDAN ANA MARIA
G2: LUCCHESI NORMA BEATRIZ
G3: MAIDANA BENJAMIN CLAUDIO
G4: DOMINGUEZ JULIO RAMON
G5: RIVADENEIRA HUGO MIGUEL
G6: DE LOS SANTOS ALBERTO
G7: MARTINEZ JUANA ROSA
G8: FERNANDEZ MARIO EUSEBIO
G9: ALONSO LEIVA MARIO IGNACIO
G10: JAUREGUI EDGARDO ALFREDO
G11: BARONGELE MONICA GLADYS
G12: LOPEZ MARGARITA IRMA
... G43: CEJAS AGUILAR MARIO CESAR
